<?xml version="1.0"?>
<robot name="mikrorobot_arm">
  <link name="base_link">
    <visual>
      <geometry>
        <box size="0.2 0.2 0.05"/>
      </geometry>
    </visual>
  </link>

  <link name="link_1">
    <visual>
      <geometry>
        <box size="0.1 0.02 0.1"/>
      </geometry>
      <origin rpy="0 0 0" xyz="0 0 0.05"/>
    </visual>
  </link>

  <joint name="joint_1" type="revolute">
    <axis xyz="0 0 1"/>
    <limit effort="1000.0" lower="-1.548" upper="1.548" velocity="0.5"/>
    <origin rpy="0 0 0" xyz="0 0 0.025"/>
    <parent link="base_link"/>
    <child link="link_1"/>
  </joint>

  <link name="link_2">
    <visual>
      <geometry>
        <box size="0.02 0.015 0.15"/>
      </geometry>
      <origin rpy="0 0 0" xyz="0 0 0.075"/>
    </visual>
  </link>

  <joint name="joint_2" type="revolute">
    <axis xyz="1 0 0"/>
    <limit effort="1000.0" lower="-1.548" upper="1.548" velocity="0.5"/>
    <origin rpy="0 0 0" xyz="0 0 0.1"/>
    <parent link="link_1"/>
    <child link="link_2"/>
  </joint>

   <link name="link_3">
    <visual>
      <geometry>
        <box size="0.02 0.015 0.08"/>
      </geometry>
      <origin rpy="0 0 0" xyz="0 0 0.04"/>
    </visual>
  </link>

  <joint name="joint_3" type="revolute">
    <axis xyz="1 0 0"/>
    <limit effort="1000.0" lower="-1.548" upper="1.548" velocity="0.5"/>
    <origin rpy="0 0 0" xyz="0 0 0.15"/>
    <parent link="link_2"/>
    <child link="link_3"/>
  </joint>

    <link name="link_4">
    <visual>
      <geometry>
        <box size="0.02 0.015 0.06"/>
      </geometry>
      <origin rpy="0 0 0" xyz="0 0 0.03"/>
    </visual>
  </link>

  <joint name="joint_4" type="revolute">
    <axis xyz="1 0 0"/>
    <limit effort="1000.0" lower="-1.548" upper="1.548" velocity="0.5"/>
    <origin rpy="0 0 0" xyz="0 0 0.08"/>
    <parent link="link_3"/>
    <child link="link_4"/>
  </joint>

</robot>
