<?xml version="1.0"?>
<robot name="mikrorobot_arm">
  <link name="base_link">
    <visual>
      <geometry>
        <box size="0.2 0.2 0.05"/>
      </geometry>
    </visual>
  </link>

  <link name="link_1">
    <visual>
      <geometry>
        <box size="0.1 0.02 0.1"/>
      </geometry>
      <origin rpy="0 0 0" xyz="0 0 0.075"/>
    </visual>
  </link>

  <joint name="joint_1" type="revolute">
    <axis xyz="0 0 1"/>
    <limit effort="1000.0" lower="-1.548" upper="1.548" velocity="0.5"/>
    <origin rpy="0 0 0" xyz="0 0 0"/>
    <parent link="base_link"/>
    <child link="link_1"/>
  </joint>

</robot>
